Workbook

Sheet Executive Dashboard
A1: Ariav ERP — delivery tracker
A2: Audit date 16 October 2026. Branch fix/rename-repair, commit c326fdf, working tree not clean. Local checks only. Not a production deployment.
A4: RELEASE DECISION
A5: =IF(OR(M13>0,I16>0,'Release Checklist'!B23>0),"Not Ready","Ready for Release")
A7: Not Ready if a critical bug is still open, a test has failed, or a mandatory checklist item is not Passed. The build passing does not change this.
E9: MODULES | G9: COMPLETED | I9: IN PROGRESS | K9: PENDING | M9: BLOCKED | O9: NOT VERIFIED
E10: =COUNTA('Module Inventory'!A2:A24) | G10: =COUNTIF('Module Inventory'!I2:I24,"Completed") | I10: =COUNTIF('Module Inventory'!I2:I24,"In Progress") | K10: =COUNTIF('Module Inventory'!I2:I24,"Pending") | M10: =COUNTIF('Module Inventory'!I2:I24,"Blocked") | O10: =COUNTIF('Module Inventory'!I2:I24,"Not Verified")
E12: TASKS | G12: TASKS DONE | I12: TASKS OPEN | K12: OPEN BUGS | M12: CRITICAL OPEN | O12: HIGH OPEN
E13: =COUNTA('Task Tracker'!A2:A19) | G13: =COUNTIF('Task Tracker'!H2:H19,"Completed") | I13: =E13-G13 | K13: =COUNTIF('Bug Tracker'!J2:J9,"Open")+COUNTIF('Bug Tracker'!J2:J9,"In Progress")+COUNTIF('Bug Tracker'!J2:J9,"Reopened")+COUNTIF('Bug Tracker'!J2:J9,"Blocked") | M13: =COUNTIFS('Bug Tracker'!H2:H9,"Critical",'Bug Tracker'!J2:J9,"Open")+COUNTIFS('Bug Tracker'!H2:H9,"Critical",'Bug Tracker'!J2:J9,"In Progress")+COUNTIFS('Bug Tracker'!H2:H9,"Critical",'Bug Tracker'!J2:J9,"Reopened") | O13: =COUNTIFS('Bug Tracker'!H2:H9,"High",'Bug Tracker'!J2:J9,"Open")+COUNTIFS('Bug Tracker'!H2:H9,"High",'Bug Tracker'!J2:J9,"In Progress")
E15: BUGS TO VERIFY | G15: CHECKS PASSED | I15: CHECKS FAILED | K15: CHECKS NOT RUN | M15: RELEASE BLOCKERS
E16: =COUNTIF('Bug Tracker'!J2:J9,"Ready for Verification") | G16: =COUNTIF('Testing & QA'!H2:H21,"Passed") | I16: =COUNTIF('Testing & QA'!H2:H21,"Failed") | K16: =COUNTIF('Testing & QA'!H2:H21,"Not Run") | M16: =COUNTIFS('Release Blockers & Risks'!I2:I16,"Yes",'Release Blockers & Risks'!N2:N16,"<>Closed")
A19: OVERALL COMPLETION (PROVISIONAL)
A20: =IF(SUM('Module Inventory'!L2:L24)=0,0,SUMPRODUCT('Module Inventory'!L2:L24,'Module Inventory'!P2:P24)/SUM('Module Inventory'!L2:L24))
A21: Weighted by the Weight column. See Module Inventory for the 40/30/30 point rule. Placeholder screens are included because they are on the navigation.
A24: TASK COMPLETION | E24: BUG RESOLUTION | I24: CHECK PASS RATE
A25: =IF(E13=0,0,G13/E13) | E25: =IF(COUNTA('Bug Tracker'!A2:A9)=0,0,COUNTIF('Bug Tracker'!J2:J9,"Verified")/COUNTA('Bug Tracker'!A2:A9)) | I25: =IF((G16+I16)=0,"No executed tests",G16/(G16+I16))
A26: Completed tasks divided by all tasks on the Task Tracker. | E26: Verified bugs divided by every bug row. Deferred and open bugs stay in the denominator. | I26: Passed divided by Passed + Failed on the Testing sheet. Not Run and Not Applicable are excluded from this rate and shown as their own counts.
A28: DJANGO SUITE | C28: TESTS PASSED | E28: TESTS FAILED | G28: TESTS RUN | I28: SUITE PASS RATE
A29: Executed 16 Oct 2026 | C29: ='Audit Evidence & Commands'!M2 | E29: ='Audit Evidence & Commands'!M3 | G29: ='Audit Evidence & Commands'!M4 | I29: =IF((C29+E29)=0,0,C29/(C29+E29))
A30: Checks passed, failed and not run count rows on Testing & QA. They are audit checks, not individual test methods. The Django suite line is the only full test run: 264 methods, 66 failures, so 198 passed. Frontend component tests and deployment smoke were not run and are not included in 198.
A32: Module status | B32: Count | D32: Task status | E32: Count | G32: Bug severity | H32: Count | J32: Bug status | K32: Count
A33: Completed | B33: =G10 | D33: Completed | E33: =G13 | G33: Critical | H33: =COUNTIF('Bug Tracker'!H$2:H$9,G33) | J33: Open | K33: =COUNTIF('Bug Tracker'!$J$2:$J$9,J33)
A34: In progress | B34: =I10 | D34: Open | E34: =I13 | G34: High | H34: =COUNTIF('Bug Tracker'!H$2:H$9,G34) | J34: Ready for Verification | K34: =COUNTIF('Bug Tracker'!$J$2:$J$9,J34)
A35: Pending | B35: =K10 | G35: Medium | H35: =COUNTIF('Bug Tracker'!H$2:H$9,G35) | J35: Verified | K35: =COUNTIF('Bug Tracker'!$J$2:$J$9,J35)
A36: Blocked | B36: =M10 | G36: Low | H36: =COUNTIF('Bug Tracker'!H$2:H$9,G36) | J36: Deferred | K36: =COUNTIF('Bug Tracker'!$J$2:$J$9,J36)
A37: Not verified | B37: =O10
A40: Testing result | B40: Count | D40: Open work by module | E40: Open tasks
A41: Passed | B41: =G16 | D41: ='Module Inventory'!B2 | E41: ='Module Inventory'!R2
A42: Failed | B42: =I16 | D42: ='Module Inventory'!B3 | E42: ='Module Inventory'!R3
A43: Not run | B43: =K16 | D43: ='Module Inventory'!B4 | E43: ='Module Inventory'!R4
A44: Not applicable | B44: =COUNTIF('Testing & QA'!H2:H21,"Not Applicable") | D44: ='Module Inventory'!B5 | E44: ='Module Inventory'!R5
D45: ='Module Inventory'!B6 | E45: ='Module Inventory'!R6
D46: ='Module Inventory'!B7 | E46: ='Module Inventory'!R7
D47: ='Module Inventory'!B8 | E47: ='Module Inventory'!R8
D48: ='Module Inventory'!B9 | E48: ='Module Inventory'!R9
D49: ='Module Inventory'!B10 | E49: ='Module Inventory'!R10
D50: ='Module Inventory'!B11 | E50: ='Module Inventory'!R11
D51: ='Module Inventory'!B12 | E51: ='Module Inventory'!R12
D52: ='Module Inventory'!B13 | E52: ='Module Inventory'!R13
D53: ='Module Inventory'!B14 | E53: ='Module Inventory'!R14
...

Sheet Module Inventory
A1: Module ID | B1: Module Name | C1: Frontend Location | D1: Backend Location | E1: Main Routes / Screens | F1: Related API Endpoints | G1: Related Models / Database Tables | H1: Main Business Functions | I1: Implementation Status | J1: Testing Status | K1: Integration Status | L1: Weight | M1: Implementation Points (0-40) | N1: Integration Points (0-30) | O1: Testing Points (0-30) | P1: Completion Percentage | Q1: Release Readiness | R1: Open Task Count | S1: Open Bug Count | T1: Blocker Count | U1: Evidence / Source References | V1: Remarks
A2: M01 | B2: Authentication and approval | C2: frontend/src/screens/auth | D2: backend/accounts | E2: Screens 1-5: login, waiting, verbal code, PIN, approval queue | F2: /api/check-credentials, /api/admin-login, /api/login, /api/verify-otp, /api/auth/me, /api/auth/admin/queue | G2: accounts_authuser, login request, user token | H2: Admin PIN login, staff password, approval, verbal code, optional approval bypass | I2: In Progress | J2: Partially verified | K2: Code inspected | L2: 3 | M2: 40 | N2: 30 | O2: 15 | P2: =IF(SUM(M2:O2)=0,0,SUM(M2:O2)/100) | Q2: Not Ready | R2: =COUNTIFS('Task Tracker'!$B$2:$B$40,A2,'Task Tracker'!$H$2:$H$40,"Pending")+COUNTIFS('Task Tracker'!$B$2:$B$40,A2,'Task Tracker'!$H$2:$H$40,"In Progress")+COUNTIFS('Task Tracker'!$B$2:$B$40,A2,'Task Tracker'!$H$2:$H$40,"Blocked")+COUNTIFS('Task Tracker'!$B$2:$B$40,A2,'Task Tracker'!$H$2:$H$40,"Not Verified") | S2: =COUNTIFS('Bug Tracker'!$B$2:$B$30,A2,'Bug Tracker'!$J$2:$J$30,"Open")+COUNTIFS('Bug Tracker'!$B$2:$B$30,A2,'Bug Tracker'!$J$2:$J$30,"In Progress")+COUNTIFS('Bug Tracker'!$B$2:$B$30,A2,'Bug Tracker'!$J$2:$J$30,"Reopened")+COUNTIFS('Bug Tracker'!$B$2:$B$30,A2,'Bug Tracker'!$J$2:$J$30,"Blocked")+COUNTIFS('Bug Tracker'!$B$2:$B$30,A2,'Bug Tracker'!$J$2:$J$30,"Ready for Verification") | T2: =COUNTIFS('Release Blockers & Risks'!$B$2:$B$30,A2,'Release Blockers & Risks'!$I$2:$I$30,"Yes",'Release Blockers & Risks'!$N$2:$N$30,"<>Closed")
A3: M02 | B3: Staff accounts | C3: frontend/src/screens/admin/StaffManagementScreen.tsx | D3: backend/accounts/staff_views.py | E3: Screen 7 Staff | F3: /api/staff/ | G3: accounts_authuser (role staff) | H3: Admin creates staff, optional login bypass, edit and delete flags forced off | I3: In Progress | J3: Partially verified | K3: Code inspected | L3: 2 | M3: 40 | N3: 25 | O3: 20 | P3: =IF(SUM(M3:O3)=0,0,SUM(M3:O3)/100) | Q3: Conditionally Ready | R3: =COUNTIFS('Task Tracker'!$B$2:$B$40,A3,'Task Tracker'!$H$2:$H$40,"Pending")+COUNTIFS('Task Tracker'!$B$2:$B$40,A3,'Task Tracker'!$H$2:$H$40,"In Progress")+COUNTIFS('Task Tracker'!$B$2:$B$40,A3,'Task Tracker'!$H$2:$H$40,"Blocked")+COUNTIFS('Task Tracker'!$B$2:$B$40,A3,'Task Tracker'!$H$2:$H$40,"Not Verified") | S3: =COUNTIFS('Bug Tracker'!$B$2:$B$30,A3,'Bug Tracker'!$J$2:$J$30,"Open")+COUNTIFS('Bug Tracker'!$B$2:$B$30,A3,'Bug Tracker'!$J$2:$J$30,"In Progress")+COUNTIFS('Bug Tracker'!$B$2:$B$30,A3,'Bug Tracker'!$J$2:$J$30,"Reopened")+COUNTIFS('Bug Tracker'!$B$2:$B$30,A3,'Bug Tracker'!$J$2:$J$30,"Blocked")+COUNTIFS('Bug Tracker'!$B$2:$B$30,A3,'Bug Tracker'!$J$2:$J$30,"Ready for Verification") | T3: =COUNTIFS('Release Blockers & Risks'!$B$2:$B$30,A3,'Release Blockers & Risks'!$I$2:$I$30,"Yes",'Release Blockers & Risks'!$N$2:$N$30,"<>Closed")
A4: M03 | B4: Branches | C4: frontend/src/screens/masters/EntityMasterScreen.tsx | D4: backend/entities | E4: Screen 36 Branch Master; header branch selector | F4: /api/entities/ | G4: entities_entity, entity brand link | H4: Branch master and the header branch used by operational lists | I4: Completed | J4: Partially verified | K4: Verified | L4: 2 | M4: 40 | N4: 30 | O4: 25 | P4: =IF(SUM(M4:O4)=0,0,SUM(M4:O4)/100) | Q4: Conditionally Ready | R4: =COUNTIFS('Task Tracker'!$B$2:$B$40,A4,'Task Tracker'!$H$2:$H$40,"Pending")+COUNTIFS('Task Tracker'!$B$2:$B$40,A4,'Task Tracker'!$H$2:$H$40,"In Progress")+COUNTIFS('Task Tracker'!$B$2:$B$40,A4,'Task Tracker'!$H$2:$H$40,"Blocked")+COUNTIFS('Task Tracker'!$B$2:$B$40,A4,'Task Tracker'!$H$2:$H$40,"Not Verified") | S4: =COUNTIFS('Bug Tracker'!$B$2:$B$30,A4,'Bug Tracker'!$J$2:$J$30,"Open")+COUNTIFS('Bug Tracker'!$B$2:$B$30,A4,'Bug Tracker'!$J$2:$J$30,"In Progress")+COUNTIFS('Bug Tracker'!$B$2:$B$30,A4,'Bug Tracker'!$J$2:$J$30,"Reopened")+COUNTIFS('Bug Tracker'!$B$2:$B$30,A4,'Bug Tracker'!$J$2:$J$30,"Blocked")+COUNTIFS('Bug Tracker'!$B$2:$B$30,A4,'Bug Tracker'!$J$2:$J$30,"Ready for Verification") | T4: =COUNTIFS('Release Blockers & Risks'!$B$2:$B$30,A4,'Release Blockers & Risks'!$I$2:$I$30,"Yes",'Release Blockers & Risks'!$N$2:$N$30,"<>Closed")
A5: M04 | B5: Brands and branch mapping | C5: frontend/src/screens/masters/BrandMasterScreen.tsx | D5: backend/brands; backend/entities | E5: Screen 37 Brand Master | F5: /api/brands/ | G5: brands_brand, entity-brand through table | H5: Brand master and which brands a branch may use | I5: In Progress | J5: Failed | K5: Code inspected | L5: 3 | M5: 40 | N5: 25 | O5: 5 | P5: =IF(SUM(M5:O5)=0,0,SUM(M5:O5)/100) | Q5: Not Ready | R5: =COUNTIFS('Task Tracker'!$B$2:$B$40,A5,'Task Tracker'!$H$2:$H$40,"Pending")+COUNTIFS('Task Tracker'!$B$2:$B$40,A5,'Task Tracker'!$H$2:$H$40,"In Progress")+COUNTIFS('Task Tracker'!$B$2:$B$40,A5,'Task Tracker'!$H$2:$H$40,"Blocked")+COUNTIFS('Task Tracker'!$B$2:$B$40,A5,'Task Tracker'!$H$2:$H$40,"Not Verified") | S5: =COUNTIFS('Bug Tracker'!$B$2:$B$30,A5,'Bug Tracker'!$J$2:$J$30,"Open")+COUNTIFS('Bug Tracker'!$B$2:$B$30,A5,'Bug Tracker'!$J$2:$J$30,"In Progress")+COUNTIFS('Bug Tracker'!$B$2:$B$30,A5,'Bug Tracker'!$J$2:$J$30,"Reopened")+COUNTIFS('Bug Tracker'!$B$2:$B$30,A5,'Bug Tracker'!$J$2:$J$30,"Blocked")+COUNTIFS('Bug Tracker'!$B$2:$B$30,A5,'Bug Tracker'!$J$2:$J$30,"Ready for Verification") | T5: =COUNTIFS('Release Blockers & Risks'!$B$2:$B$30,A5,'Release Blockers & Risks'!$I$2:$I$30,"Yes",'Release Blockers & Risks'!$N$2:$N$30,"<>Closed")
A6: M05 | B6: Categories | C6: frontend/src/screens/masters/CategoryMasterScreen.tsx | D6: backend/categories | E6: Screen 38 Category Master | F6: /api/categories/ | G6: categories category tables | H6: Category and subcategory master | I6: Completed | J6: Partially verified | K6: Verified | L6: 1 | M6: 40 | N6: 30 | O6: 25 | P6: =IF(SUM(M6:O6)=0,0,SUM(M6:O6)/100) | Q6: Conditionally Ready | R6: =COUNTIFS('Task Tracker'!$B$2:$B$40,A6,'Task Tracker'!$H$2:$H$40,"Pending")+COUNTIFS('Task Tracker'!$B$2:$B$40,A6,'Task Tracker'!$H$2:$H$40,"In Progress")+COUNTIFS('Task Tracker'!$B$2:$B$40,A6,'Task Tracker'!$H$2:$H$40,"Blocked")+COUNTIFS('Task Tracker'!$B$2:$B$40,A6,'Task Tracker'!$H$2:$H$40,"Not Verified") | S6: =COUNTIFS('Bug Tracker'!$B$2:$B$30,A6,'Bug Tracker'!$J$2:$J$30,"Open")+COUNTIFS('Bug Tracker'!$B$2:$B$30,A6,'Bug Tracker'!$J$2:$J$30,"In Progress")+COUNTIFS('Bug Tracker'!$B$2:$B$30,A6,'Bug Tracker'!$J$2:$J$30,"Reopened")+COUNTIFS('Bug Tracker'!$B$2:$B$30,A6,'Bug Tracker'!$J$2:$J$30,"Blocked")+COUNTIFS('Bug Tracker'!$B$2:$B$30,A6,'Bug Tracker'!$J$2:$J$30,"Ready for Verification") | T6: =COUNTIFS('Release Blockers & Risks'!$B$2:$B$30,A6,'Release Blockers & Risks'!$I$2:$I$30,"Yes",'Release Blockers & Risks'!$N$2:$N$30,"<>Closed")
A7: M06 | B7: Product catalogue | C7: frontend/src/screens/masters/ProductCatalogueScreen.tsx | D7: backend/products | E7: Screen 39 Product Catalogue | F7: /api/products/ | G7: products_product | H7: Brand SKUs. Catalogue brand list follows the header branch. | I7: In Progress | J7: Partially verified | K7: Code inspected | L7: 2 | M7: 35 | N7: 25 | O7: 15 | P7: =IF(SUM(M7:O7)=0,0,SUM(M7:O7)/100) | Q7: Conditionally Ready | R7: =COUNTIFS('Task Tracker'!$B$2:$B$40,A7,'Task Tracker'!$H$2:$H$40,"Pending")+COUNTIFS('Task Tracker'!$B$2:$B$40,A7,'Task Tracker'!$H$2:$H$40,"In Progress")+COUNTIFS('Task Tracker'!$B$2:$B$40,A7,'Task Tracker'!$H$2:$H$40,"Blocked")+COUNTIFS('Task Tracker'!$B$2:$B$40,A7,'Task Tracker'!$H$2:$H$40,"Not Verified") | S7: =COUNTIFS('Bug Tracker'!$B$2:$B$30,A7,'Bug Tracker'!$J$2:$J$30,"Open")+COUNTIFS('Bug Tracker'!$B$2:$B$30,A7,'Bug Tracker'!$J$2:$J$30,"In Progress")+COUNTIFS('Bug Tracker'!$B$2:$B$30,A7,'Bug Tracker'!$J$2:$J$30,"Reopened")+COUNTIFS('Bug Tracker'!$B$2:$B$30,A7,'Bug Tracker'!$J$2:$J$30,"Blocked")+COUNTIFS('Bug Tracker'!$B$2:$B$30,A7,'Bug Tracker'!$J$2:$J$30,"Ready for Verification") | T7: =COUNTIFS('Release Blockers & Risks'!$B$2:$B$30,A7,'Release Blockers & Risks'!$I$2:$I$30,"Yes",'Release Blockers & Risks'!$N$2:$N$30,"<>Closed")
A8: M07 | B8: Parties | C8: frontend/src/screens/masters/PartyMasterScreen.tsx | D8: backend/customers | E8: Screen 23 Party Master | F8: /api/customers/ | G8: customers_customer, customer-entity link | H8: Party master, codes, GSTIN and branch links | I8: In Progress | J8: Failed | K8: Code inspected | L8: 3 | M8: 40 | N8: 25 | O8: 10 | P8: =IF(SUM(M8:O8)=0,0,SUM(M8:O8)/100) | Q8: Not Ready | R8: =COUNTIFS('Task Tracker'!$B$2:$B$40,A8,'Task Tracker'!$H$2:$H$40,"Pending")+COUNTIFS('Task Tracker'!$B$2:$B$40,A8,'Task Tracker'!$H$2:$H$40,"In Progress")+COUNTIFS('Task Tracker'!$B$2:$B$40,A8,'Task Tracker'!$H$2:$H$40,"Blocked")+COUNTIFS('Task Tracker'!$B$2:$B$40,A8,'Task Tracker'!$H$2:$H$40,"Not Verified") | S8: =COUNTIFS('Bug Tracker'!$B$2:$B$30,A8,'Bug Tracker'!$J$2:$J$30,"Open")+COUNTIFS('Bug Tracker'!$B$2:$B$30,A8,'Bug Tracker'!$J$2:$J$30,"In Progress")+COUNTIFS('Bug Tracker'!$B$2:$B$30,A8,'Bug Tracker'!$J$2:$J$30,"Reopened")+COUNTIFS('Bug Tracker'!$B$2:$B$30,A8,'Bug Tracker'!$J$2:$J$30,"Blocked")+COUNTIFS('Bug Tracker'!$B$2:$B$30,A8,'Bug Tracker'!$J$2:$J$30,"Ready for Verification") | T8: =COUNTIFS('Release Blockers & Risks'!$B$2:$B$30,A8,'Release Blockers & Risks'!$I$2:$I$30,"Yes",'Release Blockers & Risks'!$N$2:$N$30,"<>Closed")
A9: M08 | B9: Price lists (Excel) | C9: frontend/src/screens/masters/PriceListScreen.tsx | D9: backend/price_lists | E9: Screen 49 Price Lists; Import from file | F9: /api/price-lists/import/preview/, /api/price-lists/import/commit/ | G9: price_lists_pricelist, pricelistentry, quality entry | H9: Seasonal Excel price lists and OCM quality workbook import | I9: Completed | J9: Partially verified | K9: Verified | L9: 2 | M9: 40 | N9: 30 | O9: 25 | P9: =IF(SUM(M9:O9)=0,0,SUM(M9:O9)/100) | Q9: Conditionally Ready | R9: =COUNTIFS('Task Tracker'!$B$2:$B$40,A9,'Task Tracker'!$H$2:$H$40,"Pending")+COUNTIFS('Task Tracker'!$B$2:$B$40,A9,'Task Tracker'!$H$2:$H$40,"In Progress")+COUNTIFS('Task Tracker'!$B$2:$B$40,A9,'Task Tracker'!$H$2:$H$40,"Blocked")+COUNTIFS('Task Tracker'!$B$2:$B$40,A9,'Task Tracker'!$H$2:$H$40,"Not Verified") | S9: =COUNTIFS('Bug Tracker'!$B$2:$B$30,A9,'Bug Tracker'!$J$2:$J$30,"Open")+COUNTIFS('Bug Tracker'!$B$2:$B$30,A9,'Bug Tracker'!$J$2:$J$30,"In Progress")+COUNTIFS('Bug Tracker'!$B$2:$B$30,A9,'Bug Tracker'!$J$2:$J$30,"Reopened")+COUNTIFS('Bug Tracker'!$B$2:$B$30,A9,'Bug Tracker'!$J$2:$J$30,"Blocked")+COUNTIFS('Bug Tracker'!$B$2:$B$30,A9,'Bug Tracker'!$J$2:$J$30,"Ready for Verification") | T9: =COUNTIFS('Release Blockers & Risks'!$B$2:$B$30,A9,'Release Blockers & Risks'!$I$2:$I$30,"Yes",'Release Blockers & Risks'!$N$2:$N$30,"<>Closed")
A10: M09 | B10: Price lists (PDF) | C10: Not built | D10: backend/price_lists/models.py BrandQualityPrice | E10: No Import PDF screen | F10: No /api/price-lists/import-pdf/ endpoint exists | G10: price_lists_brandqualityprice; price list source columns | H10: OCM Summer/Winter PDF extraction, preview, commit and rate lookup were specified and not built | I10: Pending | J10: Not verified | K10: Not verified | L10: 2 | M10: 10 | N10: 0 | O10: 0 | P10: =IF(SUM(M10:O10)=0,0,SUM(M10:O10)/100) | Q10: Not Ready | R10: =COUNTIFS('Task Tracker'!$B$2:$B$40,A10,'Task Tracker'!$H$2:$H$40,"Pending")+COUNTIFS('Task Tracker'!$B$2:$B$40,A10,'Task Tracker'!$H$2:$H$40,"In Progress")+COUNTIFS('Task Tracker'!$B$2:$B$40,A10,'Task Tracker'!$H$2:$H$40,"Blocked")+COUNTIFS('Task Tracker'!$B$2:$B$40,A10,'Task Tracker'!$H$2:$H$40,"Not Verified") | S10: =COUNTIFS('Bug Tracker'!$B$2:$B$30,A10,'Bug Tracker'!$J$2:$J$30,"Open")+COUNTIFS('Bug Tracker'!$B$2:$B$30,A10,'Bug Tracker'!$J$2:$J$30,"In Progress")+COUNTIFS('Bug Tracker'!$B$2:$B$30,A10,'Bug Tracker'!$J$2:$J$30,"Reopened")+COUNTIFS('Bug Tracker'!$B$2:$B$30,A10,'Bug Tracker'!$J$2:$J$30,"Blocked")+COUNTIFS('Bug Tracker'!$B$2:$B$30,A10,'Bug Tracker'!$J$2:$J$30,"Ready for Verification") | T10: =COUNTIFS('Release Blockers & Risks'!$B$2:$B$30,A10,'Release Blockers & Risks'!$I$2:$I$30,"Yes",'Release Blockers & Risks'!$N$2:$N$30,"<>Closed")
A11: M10 | B11: Purchase orders | C11: frontend/src/screens/core/PurchaseOrderScreen.tsx | D11: backend/purchase_orders | E11: Screen 40 Purchase Orders | F11: /api/purchase-orders/ | G11: purchase_orders_purchaseorder, purchaseorderline | H11: Manual and imported POs, status, lines, Excel import | I11: In Progress | J11: Partially verified | K11: Code inspected | L11: 3 | M11: 40 | N11: 25 | O11: 15 | P11: =IF(SUM(M11:O11)=0,0,SUM(M11:O11)/100) | Q11: Not Ready | R11: =COUNTIFS('Task Tracker'!$B$2:$B$40,A11,'Task Tracker'!$H$2:$H$40,"Pending")+COUNTIFS('Task Tracker'!$B$2:$B$40,A11,'Task Tracker'!$H$2:$H$40,"In Progress")+COUNTIFS('Task Tracker'!$B$2:$B$40,A11,'Task Tracker'!$H$2:$H$40,"Blocked")+COUNTIFS('Task Tracker'!$B$2:$B$40,A11,'Task Tracker'!$H$2:$H$40,"Not Verified") | S11: =COUNTIFS('Bug Tracker'!$B$2:$B$30,A11,'Bug Tracker'!$J$2:$J$30,"Open")+COUNTIFS('Bug Tracker'!$B$2:$B$30,A11,'Bug Tracker'!$J$2:$J$30,"In Progress")+COUNTIFS('Bug Tracker'!$B$2:$B$30,A11,'Bug Tracker'!$J$2:$J$30,"Reopened")+COUNTIFS('Bug Tracker'!$B$2:$B$30,A11,'Bug Tracker'!$J$2:$J$30,"Blocked")+COUNTIFS('Bug Tracker'!$B$2:$B$30,A11,'Bug Tracker'!$J$2:$J$30,"Ready for Verification") | T11: =COUNTIFS('Release Blockers & Risks'!$B$2:$B$30,A11,'Release Blockers & Risks'!$I$2:$I$30,"Yes",'Release Blockers & Risks'!$N$2:$N$30,"<>Closed")
A12: M11 | B12: Dispatches and reconciliation | C12: frontend/src/screens/core/DispatchScreen.tsx; PoDispatchReconciliationScreen.tsx | D12: backend/dispatches | E12: Screens 41 and reconciliation | F12: /api/dispatches/; reconciliation action | G12: dispatches_dispatch, dispatch lines | H12: Record dispatch, Excel import, PO versus dispatch reconciliation | I12: In Progress | J12: Failed | K12: Code inspected | L12: 3 | M12: 40 | N12: 25 | O12: 5 | P12: =IF(SUM(M12:O12)=0,0,SUM(M12:O12)/100) | Q12: Not Ready | R12: =COUNTIFS('Task Tracker'!$B$2:$B$40,A12,'Task Tracker'!$H$2:$H$40,"Pending")+COUNTIFS('Task Tracker'!$B$2:$B$40,A12,'Task Tracker'!$H$2:$H$40,"In Progress")+COUNTIFS('Task Tracker'!$B$2:$B$40,A12,'Task Tracker'!$H$2:$H$40,"Blocked")+COUNTIFS('Task Tracker'!$B$2:$B$40,A12,'Task Tracker'!$H$2:$H$40,"Not Verified") | S12: =COUNTIFS('Bug Tracker'!$B$2:$B$30,A12,'Bug Tracker'!$J$2:$J$30,"Open")+COUNTIFS('Bug Tracker'!$B$2:$B$30,A12,'Bug Tracker'!$J$2:$J$30,"In Progress")+COUNTIFS('Bug Tracker'!$B$2:$B$30,A12,'Bug Tracker'!$J$2:$J$30,"Reopened")+COUNTIFS('Bug Tracker'!$B$2:$B$30,A12,'Bug Tracker'!$J$2:$J$30,"Blocked")+COUNTIFS('Bug Tracker'!$B$2:$B$30,A12,'Bug Tracker'!$J$2:$J$30,"Ready for Verification") | T12: =COUNTIFS('Release Blockers & Risks'!$B$2:$B$30,A12,'Release Blockers & Risks'!$I$2:$I$30,"Yes",'Release Blockers & Risks'!$N$2:$N$30,"<>Closed")
A13: M12 | B13: Invoices | C13: frontend/src/screens/core/InvoiceScreen.tsx | D13: backend/invoices | E13: Screen 42 Invoices | F13: /api/invoices/ | G13: invoices_invoice, invoiceline | H13: Invoice against dispatched quantity, tax, issue, cancel, trace | I13: In Progress | J13: Failed | K13: Code inspected | L13: 3 | M13: 40 | N13: 25 | O13: 5 | P13: =IF(SUM(M13:O13)=0,0,SUM(M13:O13)/100) | Q13: Not Ready | R13: =COUNTIFS('Task Tracker'!$B$2:$B$40,A13,'Task Tracker'!$H$2:$H$40,"Pending")+COUNTIFS('Task Tracker'!$B$2:$B$40,A13,'Task Tracker'!$H$2:$H$40,"In Progress")+COUNTIFS('Task Tracker'!$B$2:$B$40,A13,'Task Tracker'!$H$2:$H$40,"Blocked")+COUNTIFS('Task Tracker'!$B$2:$B$40,A13,'Task Tracker'!$H$2:$H$40,"Not Verified") | S13: =COUNTIFS('Bug Tracker'!$B$2:$B$30,A13,'Bug Tracker'!$J$2:$J$30,"Open")+COUNTIFS('Bug Tracker'!$B$2:$B$30,A13,'Bug Tracker'!$J$2:$J$30,"In Progress")+COUNTIFS('Bug Tracker'!$B$2:$B$30,A13,'Bug Tracker'!$J$2:$J$30,"Reopened")+COUNTIFS('Bug Tracker'!$B$2:$B$30,A13,'Bug Tracker'!$J$2:$J$30,"Blocked")+COUNTIFS('Bug Tracker'!$B$2:$B$30,A13,'Bug Tracker'!$J$2:$J$30,"Ready for Verification") | T13: =COUNTIFS('Release Blockers & Risks'!$B$2:$B$30,A13,'Release Blockers & Risks'!$I$2:$I$30,"Yes",'Release Blockers & Risks'!$N$2:$N$30,"<>Closed")
... A24: M23 | B24: Party statement import | C24: frontend/src/screens/reports/BrandStatementReport.tsx | D24: backend/statements; backend/customers statement-report | E24: Party Balance report | F24: /api/customers/statement-report/ | G24: customer statement and statement entry tables | H24: Load a party statement file and show opening, movement and closing | I24: Completed | J24: Partially verified | K24: Verified | L24: 2 | M24: 40 | N24: 30 | O24: 25 | P24: =IF(SUM(M24:O24)=0,0,SUM(M24:O24)/100) | Q24: Conditionally Ready | R24: =COUNTIFS('Task Tracker'!$B$2:$B$40,A24,'Task Tracker'!$H$2:$H$40,"Pending")+COUNTIFS('Task Tracker'!$B$2:$B$40,A24,'Task Tracker'!$H$2:$H$40,"In Progress")+COUNTIFS('Task Tracker'!$B$2:$B$40,A24,'Task Tracker'!$H$2:$H$40,"Blocked")+COUNTIFS('Task Tracker'!$B$2:$B$40,A24,'Task Tracker'!$H$2:$H$40,"Not Verified") | S24: =COUNTIFS('Bug Tracker'!$B$2:$B$30,A24,'Bug Tracker'!$J$2:$J$30,"Open")+COUNTIFS('Bug Tracker'!$B$2:$B$30,A24,'Bug Tracker'!$J$2:$J$30,"In Progress")+COUNTIFS('Bug Tracker'!$B$2:$B$30,A24,'Bug Tracker'!$J$2:$J$30,"Reopened")+COUNTIFS('Bug Tracker'!$B$2:$B$30,A24,'Bug Tracker'!$J$2:$J$30,"Blocked")+COUNTIFS('Bug Tracker'!$B$2:$B$30,A24,'Bug Tracker'!$J$2:$J$30,"Ready for Verification") | T24: =COUNTIFS('Release Blockers & Risks'!$B$2:$B$30,A24,'Release Blockers & Risks'!$I$2:$I$30,"Yes",'Release Blockers & Risks'!$N$2:$N$30,"<>Closed")
A26: Weighting
A27: Completion = (implementation points + integration points + testing points) / 100. Caps are 40, 30 and 30. A module is not given 30 testing points unless this audit's run showed no failures for that area. Overall project completion on the dashboard is the weight-weighted average of this column. It is provisional: placeholder screens are in the navigation, so they are in scope, but a full statutory ledger was not specified as a finished subsystem in code.

Sheet Task Tracker
A1: Task ID | B1: Module | C1: Task Title | D1: Detailed Description | E1: Task Type | F1: Priority | G1: Business Impact | H1: Status | I1: Estimated Hours | J1: Actual Hours | K1: Owner | L1: Dependencies | M1: Acceptance Criteria | N1: Verification Method | O1: Evidence | P1: Target Date | Q1: Delivery Criticality | R1: Remarks
A2: T01 | B2: M04 | C2: Repair branch-brand coverage in automated flows | D2: 65 tests fail because purchase-order create returns 400: the brand is not mapped to the branch. Decide whether fixtures must create the EntityBrand link, or whether the rule should not apply to those flows. Then re-run the suite. | E2: Bug Fix | F2: Critical | G2: The suite can no longer prove dispatch, invoice, payment, ledger or party-scope behaviour. | H2: Pending | I2: 8 | K2: Unassigned | L2: None | M2: manage.py test reports 0 failures caused by brand-not-mapped. | N2: Re-run backend/purchase_orders, invoices, dispatches, payments, ledger, customers and accounts.tests_customer_scope. | O2: 16 Oct 2026 suite: 66 failures, 65 with brand-not-mapped 400. | P2: 46311 | Q2: Release blocker | R2: Do not weaken the mapping rule only to make tests green unless the business rule is wrong.
A3: T02 | B3: M11 | C3: Repair the OCM dispatch import golden mismatch | D3: test_golden_ocm_all_groups_preview_commit_and_rows failed because the preview payload and the commit payload are not the same shape. | E3: Bug Fix | F3: High | G3: A dispatch file can look acceptable in preview and then commit differently. | H3: Pending | I3: 4 | K3: Unassigned | L3: T01 | M3: The golden test passes without changing expected business totals by hand. | N3: Run dispatches.tests_import. The assertion compared preview and commit structures. | O3: FAIL line in the 16 Oct 2026 run. | P3: 46311 | Q3: Release blocker | R3: One failure. Separate from the 65 mapping failures.
A4: T03 | B4: M21 | C4: Stop the year-end screen from pretending to close the year | D4: handleExecuteClosing accepts PIN 1984 or any PIN of at least 4 characters, writes a local audit line, and sets the header financial year to 2026-27. No server close runs. | E4: Bug Fix | F4: Critical | G4: The header year then filters purchase orders, invoices, payments and other lists. A false close changes what every page shows. | H4: Pending | I4: 4 | K4: Unassigned | L4: None | M4: The screen cannot change the global year, and it does not say the books were closed. | N4: Code review of YearEndClosingScreen.tsx and a browser check that the header year stays unchanged. | O4: frontend/src/screens/admin/YearEndClosingScreen.tsx lines 17-26. | P4: 46311 | Q4: Release blocker | R4: Removing the screen from navigation is an acceptable release fix. Building a real close is not possible today.
A5: T04 | B5: M18 | C5: Remove sample statutory screens from the release navigation | D5: Sales register, purchase register, trial balance, balance sheet, profit and loss, and bank/cash book render hard-coded sample rows. They do not call the reports API or ledger lines. | E5: Bug Fix | F5: High | G5: A reader can treat sample money figures as the company's books. | H5: Pending | I5: 6 | K5: Unassigned | L5: None | M5: Those screens are not reachable in the release build, or they are labelled sample and show no amounts. | N5: Search the screens for hard-coded arrays and confirm the navigation no longer opens them. | O5: TrialBalanceScreen.tsx and SalesRegisterScreen.tsx. | P5: 46311 | Q5: Release blocker | R5: Building real statutory books is out of today's capacity. Hiding the screens is the safe scope.
A6: T05 | B6: M19 | C6: Remove sample voucher and order-form screens from navigation | D6: Bank receipt, cash receipt, payment voucher, credit note, debit note, material return and order form keep local sample state. transactions tables are not used by those screens. | E6: Bug Fix | F6: High | G6: Users can believe a voucher was posted when nothing was saved. | H6: Pending | I6: 6 | K6: Unassigned | L6: None | M6: The screens are not in the release navigation, or they state that they do not post. | N6: Confirm no Api import remains and the icon rail does not open them. | O6: BankReceiptVoucherScreen.tsx has no API calls. OrderFormScreen.tsx initialises ordersList locally. | P6: 46311 | Q6: Release blocker | R6: Same treatment as the statutory screens.
A7: T06 | B7: M21 | C7: Remove the simulated backup screen | D7: BackupScreen keeps a local list and animates success. It does not dump or copy the database. | E7: Bug Fix | F7: High | G7: An operator can believe a backup exists. | H7: Pending | I7: 2 | K7: Unassigned | L7: T09 | M7: The screen is gone or it only tells the operator that backup is a manual database operation. | N7: Read BackupScreen.tsx and confirm no file is written. | O7: frontend/src/screens/admin/BackupScreen.tsx | P7: 46311 | Q7: Release blocker
A8: T07 | B8: M09 | C8: Build the OCM PDF price-list import | D8: BrandQualityPrice and the price-list source columns exist. There is no preview endpoint, no commit endpoint, no second text extraction, and no UI step. | E8: Development | F8: High | G8: Summer 2026 and Winter 2025 PDF prices cannot be loaded or used on a purchase order. | H8: Pending | I8: 24 | K8: Unassigned | L8: Approved schema, which is already migrated | M8: Preview and commit match a text-layer extract, and purchase-order rate lookup follows the approved rules. | N8: New tests plus a skipped golden test when the real PDFs are present. | O8: models.py BrandQualityPrice; no import-pdf route in price_lists. | P8: 46312 | Q8: Not finishable today | R8: Leave this out of today's release scope.
A9: T08 | B9: M22 | C9: Point the audit screen at the server trail | D9: The screen filters ErpContext auditLogs. The export control only shows a toast. /api/auth/audit-trail exists and is unused by the screen. | E9: Integration | F9: Medium | G9: The forensic screen does not show the server audit. | H9: Pending | I9: 4 | K9: Unassigned | L9: None | M9: The screen lists server audit rows for the signed-in admin and does not offer a fake signed export. | N9: Call the audit endpoint and compare the screen. | O9: AuditLogScreen.tsx | P9: 46312 | Q9: Not finishable as a full feature today
A10: T09 | B10: M21 | C10: Confirm a database backup before any further migration | D10: Migrations 0010 and price_lists 0003 were applied on 15 Oct 2026. This audit did not see a backup file or a restore test. | E10: Database | F10: Critical | G10: There is no demonstrated way back if a later migration is wrong. | H10: Not Verified | I10: 2 | K10: Unassigned | L10: Database owner | M10: A backup file name, time and restore note are recorded outside this workbook. Do not paste secrets. | N10: Operator confirms the backup. This audit cannot verify a file that was not provided. | O10: showmigrations listed no unapplied migrations. Backup command was not run. | P10: 46311 | Q10: Release blocker | R10: Assumption: nobody has confirmed a backup to this audit.
A11: T10 | B11: M01 | C11: Review production settings without printing secrets | D11: DEBUG defaults to true when DJANGO_DEBUG is unset. An empty DJANGO_SECRET_KEY is replaced by a dev-only key when DEBUG is true. ALLOWED_HOSTS become * when DEBUG is true. | E11: Security | F11: High | G11: A production process started with defaults would run in debug with a known key. | H11: Not Verified | I11: 4 | K11: Unassigned | L11: Deployment host | M11: The host process has DJANGO_DEBUG false and a secret key that is not in git. Values must not be copied into this workbook. | N11: Inspect the service environment names only. | O11: backend/config/settings.py lines 10-18 and 134-142. | P11: 46311 | Q11: Release blocker | R11: Suspected until the host environment is inspected. .env is gitignored and was not read.
A12: T11 | B12: M10 | C12: Review the uncommitted working tree before any release tag | D12: Branch fix/rename-repair at c326fdf. git diff --stat reported 103 files changed, 4090 insertions and 1084 deletions. git status --porcelain had 131 lines. | E12: Deployment | F12: Critical | G12: What is running is not the last commit. A release tag would not match the working tree. | H12: Pending | I12: 8 | K12: Unassigned | L12: T01 | M12: The released commit contains only reviewed files. Generated caches and local databases are not included. | N12: git status and a human review. This audit did not commit. | O12: git status and git diff --stat on 16 Oct 2026. | P12: 46311 | Q12: Release blocker | R12: Do not commit from this audit.
A13: T12 | B13: M11 | C13: Re-run the backend suite after T01 and T02 | D13: The 16 Oct 2026 run is the baseline: 264 tests, 198 passed, 66 failed, exit code 1. | E13: Testing | F13: Critical | G13: No later change is known to be safe until this is green for the trading flow. | H13: Pending | I13: 2 | K13: Unassigned | L13: T01, T02 | M13: Exit code 0, or a written list of remaining failures with owners. | N13: python manage.py test from backend/.venv. | O13: Terminal 39737. | P13: 46311 | Q13: Release blocker
A14: T13 | B14: M06 | C14: Run the frontend component tests that have no npm script | D14: package.json lint is tsc --noEmit. There is no npm test script. PurchaseOrderPipeline.test.tsx and other frontend tests were not executed. | E14: Testing | F14: Medium | G14: Typecheck does not prove screen behaviour. | H14: Not Verified | I14: 3 | K14: Unassigned | L14: None | M14: The existing frontend tests are executed and their pass or fail count is recorded. | N14: Add a script only if asked. This audit must not change application code, so they stay Not Run. | O14: frontend/package.json scripts. | P14: 46312 | Q14: Not a code defect
A15: T14 | B15: M16 | C15: Exercise the header year and month on one trading screen | D15: The header period is stored and operational lists send that date range. dateFilters.test.ts passed. No browser pass confirmed a list changing with the header. | E15: Testing | F15: Medium | G15: A wrong period would hide or show the wrong documents. | H15: Not Verified | I15: 2 | K15: Unassigned | L15: None | M15: Changing FY in the header changes the purchase-order or invoice rows to that range only. | N15: Browser check against a known document date. | O15: frontend/src/utils/dateFilters.ts and the list screens edited on 16 Oct 2026. | P15: 46311 | Q15: Should be checked before demo
A16: T15 | B16: M17 | C16: Document the bad-debt report gap | D16: reports/services.py says bad-debt totals are not populated until a write-off module exists. | E16: Documentation | F16: Low | G16: That one report is empty by design. | H16: Deferred | I16: 1 | K16: Unassigned | L16: A write-off module, which does not exist | M16: The report label says it is not fed by write-offs. | N16: Read the service TODO. | O16: backend/reports/services.py line 215. | P16: 46326 | Q16: Not in today's scope
A17: T16 | B17: M08 | C17: Excel price-list import is in the tree and its tests did not fail | D17: Recorded so the tracker contains finished work as well as gaps. This is not a claim that PDF import exists. | E17: Development | F17: Medium | G17: Excel price lists can be imported in test. | H17: Completed | I17: 0 | K17: Unassigned | L17: None | M17: price_lists tests produced no FAIL lines on 16 Oct 2026. | N17: Already executed in the full suite. | O17: No FAIL lines for price_lists. | P17: 46311 | Q17: Done for Excel only | R17: Actual hours were not recorded.
A18: T17 | B18: M16 | C18: Frontend typecheck and production build succeeded | D18: npm run lint is tsc --noEmit and exited 0. npm run build exited 0 in 25.67 seconds with a chunk-size warning. | E18: Testing | F18: High | G18: The UI compiles and builds. That does not clear the test failures. | H18: Completed | I18: 0 | K18: Unassigned | L18: None | M18: Both commands exit 0. | N18: Already executed. | O18: Terminal output 16 Oct 2026. | P18: 46311 | Q18: Done | R18: The JavaScript bundle is 1,567 kB. That is a warning, not a failed build.
A19: T18 | B19: M03 | C19: Django system check and migration scan | D19: manage.py check reported no issues. showmigrations --plan filtered for unapplied lines returned none. | E19: Database | F19: High | G19: The code's migrations match the database that was checked. This is not a backup. | H19: Completed | I19: 0 | K19: Unassigned | L19: None | M19: check exit 0 and no unapplied plan lines. | N19: Already executed. | O19: 16 Oct 2026 command output. | P19: 46311 | Q19: Done
H21: Open hours | I21: =SUMIF(H2:H19,"<>Completed",I2:I19)

Sheet Bug Tracker
A1: Bug ID | B1: Module | C1: Bug Title | D1: Description | E1: Reproduction Steps | F1: Expected Result | G1: Actual Result | H1: Severity | I1: Priority | J1: Status | K1: Root Cause | L1: Proposed Fix | M1: Owner | N1: Estimated Fix Hours | O1: Related Task ID | P1: Regression Test | Q1: Verification Evidence | R1: Date Identified | S1: Target Fix Date | T1: Remarks
A2: B01 | B2: M04 | C2: Purchase-order create rejects brands that are not mapped to the branch | D2: Creating a purchase order for a brand that is not linked to the selected branch returns HTTP 400. Sixty-five automated tests fail on this response before they can test dispatch, invoice, payment or ledger behaviour. | E2: Run python manage.py test from backend with the project virtualenv. Inspect any FAIL whose body contains brand_id and not mapped to branch. | F2: Either the fixture brands are mapped and the later assertions run, or the product rule is documented and the tests are updated on purpose. | G2: 400 with messages such as Brand Payment Mills is not mapped to branch Gujarat Payments. Counts: payments 15, accounts 13, invoices 16 of which most are this setup error, dispatches 8, ledger 7, customers 3, notifications 2, plus one purchase-order import case for OCM 2 and Aditi. | H2: High | I2: Critical | J2: Open | K2: Entity-brand mapping is enforced. The automated fixtures still create a brand and a branch that are not linked. | L2: Link the fixture brand to the fixture branch, then re-run. Do not remove the check unless the business rule is withdrawn. | M2: Unassigned | N2: 8 | O2: T01 | P2: Full backend suite | Q2: 16 Oct 2026: 66 failures, 65 of this message family. | R2: 46311 | S2: 46311 | T2: Not marked Critical because the live rule may be correct. It is a release blocker because the trading tests no longer prove the flows.
A3: B02 | B3: M11 | C3: OCM dispatch import preview and commit do not match | D3: The golden all-groups test compares the preview structure with the commit structure and they differ. | E3: Run dispatches import tests, specifically test_golden_ocm_all_groups_preview_commit_and_rows. | F3: Commit persists the same groups the preview showed. | G3: AssertionError comparing a preview dict with a commit dict. The log shows a long structural mismatch, not a brand-mapping 400. | H3: High | I3: High | J3: Open | K3: Not isolated beyond the failing assertion in this audit. | L3: Compare the two payloads in that test and make commit follow the preview contract. | M3: Unassigned | N3: 4 | O3: T02 | P3: dispatches.tests_import golden test | Q3: Single FAIL line on 16 Oct 2026. | R3: 46311 | S3: 46311 | T3: Confirmed test failure. The business numbers inside the mismatch were not re-derived in this audit.
A4: B03 | B4: M21 | C4: Year-end screen reports a close that does not happen | D4: The close handler checks the PIN with: reject only when the PIN is not 1984 and its length is under 4. Any longer PIN passes. It then sets the header financial year to 2026-27 and shows a success message. | E4: Open screen 10, enter any 4-character PIN, and confirm. | F4: A real close would be refused or performed on the server. The header year would not change as a side effect of a fake close. | G4: The handler sets confirmed close, writes a local audit line, shows a flash, and calls setFinancialYear('2026-27'). | H4: Critical | I4: Critical | J4: Open | K4: The screen was written as a local demonstration. The condition is the wrong way around for a strict PIN check. | L4: Remove the screen from navigation or make it explain that no close is posted, and do not change the header year. | M4: Unassigned | N4: 4 | O4: T03 | P4: Code inspection. No automated test covers this screen. | Q4: YearEndClosingScreen.tsx handleExecuteClosing. | R4: 46311 | S4: 46311 | T4: Confirmed by reading the source. Not executed in the browser during this audit. Severity is Critical because the header year filters live lists.
A5: B04 | B5: M18 | C5: Statutory screens display sample books | D5: Trial balance, balance sheet, profit and loss, sales register, purchase register, and bank/cash book ship with hard-coded sample rows. | E5: Open screens 29, 30, 32, 33, 34 or 35. | F5: Figures come from posted ledger lines for the header period, or the screen is absent. | G5: The components initialise local arrays. They do not call the reports API. | H5: High | I5: High | J5: Open | K5: The screens were built as static layouts. LedgerLine exists but is not read here. | L5: Remove them from the release navigation until they read posted data. | M5: Unassigned | N5: 6 | O5: T04 | P5: Source inspection. | Q5: TrialBalanceScreen.tsx and SalesRegisterScreen.tsx. | R5: 46311 | S5: 46311 | T5: Confirmed. Sample party names in those files are demo text, not a live customer extract, and are not copied into this workbook.
A6: B05 | B6: M19 | C6: Voucher and order-form screens do not post | D6: The voucher, note, material-return and order-form screens keep local state. The transactions tables are unused by those screens. | E6: Open screens 13-15, 17-20 or the order form and try to save. | F6: A posted voucher or order exists in the database, or the screen is not offered. | G6: No API client calls were found in the bank-receipt or credit/debit screens. Order form initialises a local list. | H6: High | I6: High | J6: Open | K6: UI prototypes were routed beside the live purchase-order flow. | L6: Remove them from navigation for this release. | M6: Unassigned | N6: 6 | O6: T05 | P6: Source inspection. | Q6: BankReceiptVoucherScreen.tsx, CreditDebitNoteScreen.tsx, OrderFormScreen.tsx. | R6: 46311 | S6: 46311
A7: B06 | B7: M21 | C7: Backup screen reports a snapshot it did not take | D7: The screen stores a local array of backup names and animates progress. | E7: Open screen 9 and start a backup. | F7: A real database backup is created, or the action is not offered. | G7: State updates only. No backup command is run. | H7: High | I7: High | J7: Open | K7: Demonstration UI. | L7: Remove the screen. | M7: Unassigned | N7: 2 | O7: T06 | P7: Source inspection. | Q7: BackupScreen.tsx | R7: 46311 | S7: 46311
A8: B07 | B8: M22 | C8: Audit screen is not the server audit trail | D8: The forensic screen filters in-memory context logs. Its export control shows a toast instead of a file. | E8: Sign in as admin, create a server audit event, open screen 8. | F8: The new server row appears. | G8: The screen never requests /api/auth/audit-trail. This was not clicked in this audit, so the runtime result is code-inspected. | H8: Medium | I8: Medium | J8: Open | K8: The screen was wired to context state. | L8: Read the API. Remove the fake export. | M8: Unassigned | N8: 4 | O8: T08 | P8: Source inspection. Not a failed automated test. | Q8: AuditLogScreen.tsx | R8: 46311 | S8: 46312 | T8: Suspected at runtime until someone opens the screen. The missing API call is confirmed in source.
A9: B08 | B9: M16 | C9: Dashboard failed when rate_source was not in the database | D9: On 15 Oct 2026 GET /api/dashboards/admin/ returned 500: unknown column purchase_orders_purchaseorderline.rate_source. | E9: Load the dashboard before migration 0010. | F9: The dashboard loads. | G9: The column was missing. Migrations purchase_orders.0010 and price_lists.0003 were applied on 15 Oct 2026. This audit did not reload the dashboard. | H9: High | I9: High | J9: Ready for Verification | K9: Model field shipped before the migration was applied. | L9: Reload the dashboard once and record the HTTP status. | M9: Unassigned | N9: 0.5 | O9: T14 | P9: dashboards.tests had no FAIL lines on 16 Oct 2026. Browser reload was not done. | Q9: Terminal log 15 Oct 2026 17:00 and migrate output the same day. | R9: 46310 | S9: 46311 | T9: Not Verified. Do not mark Verified from the migration command alone.

Sheet Testing & QA
A1: Test ID | B1: Module | C1: Test Category | D1: Test Scenario | E1: Preconditions | F1: Expected Result | G1: Actual Result | H1: Test Status | I1: Execution Date | J1: Environment | K1: Related Bug ID | L1: Evidence / Log Reference | M1: Notes
A2: QA01 | B2: M16 | C2: Django system check | D2: python manage.py check | E2: Project virtualenv, backend directory | F2: No issues | G2: System check identified no issues (0 silenced). Exit 0. | H2: Passed | I2: 46311 | J2: Local Windows, backend/.venv | L2: 16 Oct 2026 check command
A3: QA02 | B3: M03 | C3: Database migrations | D3: showmigrations --plan filtered for unapplied lines | E3: Same environment | F3: No unapplied migrations | G3: The filter printed no unapplied lines. Exit 0. | H3: Passed | I3: 46311 | J3: Local Windows, backend/.venv | L3: 16 Oct 2026 | M3: This does not prove a backup exists.
A4: QA03 | B4: M06 | C4: Frontend typecheck | D4: npm run lint (tsc --noEmit) | E4: frontend directory | F4: Exit 0 | G4: Exit 0. No type errors printed. | H4: Passed | I4: 46311 | J4: Local Windows, frontend npm | L4: 16 Oct 2026 lint | M4: The script name is lint. It is the typecheck.
A5: QA04 | B5: M06 | C5: Production build | D5: npm run build | E5: frontend directory | F5: Vite build completes | G5: Exit 0. Built in 25.67s. Chunk size warning: index JS 1,567.10 kB. | H5: Passed | I5: 46311 | J5: Local Windows, Vite 6.4.3 | L5: 16 Oct 2026 build | M5: Warning is not a failure. Not a deployment.
A6: QA05 | B6: M16 | C6: Frontend unit | D6: npx tsx src/utils/dateFilters.test.ts | E6: frontend directory | F6: Helper assertions pass | G6: Printed: invoice date filter helper tests passed. Exit 0. | H6: Passed | I6: 46311 | J6: Local Windows, tsx | L6: Same-day run before the suite | M6: Covers financial-year date maths only.
A7: QA06 | B7: M10 | C7: Backend suite | D7: python manage.py test --verbosity 1 | E7: backend/.venv, isolated test database | F7: All tests pass | G7: 264 tests in 324.962s. 198 passed, 66 failed, exit 1. Test database created and destroyed. | H7: Failed | I7: 46311 | J7: Local Windows, Django test database | K7: B01, B02 | L7: Terminal log of the 16 Oct 2026 run | M7: Passed count is 264 minus 66. No error or skip summary was printed.
A8: QA07 | B8: M13 | C8: API tests | D8: payments app failures inside the suite | E8: Same run | F8: Payment tests pass | G8: 15 FAIL lines. All shown assertions are brand-not-mapped 400 on PO create. | H8: Failed | I8: 46311 | J8: Same | K8: B01 | L8: payments.tests
A9: QA08 | B9: M01 | C9: Role-based access | D9: accounts app failures inside the suite | E9: Same run | F9: Scope tests pass | G9: 13 FAIL lines. Names are the customer-scope tests, including session revocation setup. Same 400. | H9: Failed | I9: 46311 | J9: Same | K9: B01 | L9: accounts.tests_customer_scope names in the FAIL list | M9: Auth lockdown and staff method names were not in the FAIL list. They are not individually certified.
A10: QA09 | B10: M12 | C10: API and calculation tests | D10: invoices app failures inside the suite | E10: Same run | F10: Invoice tests pass | G10: 16 FAIL lines. Bodies shown are brand-not-mapped 400, so tax and trace assertions were not reached. | H10: Failed | I10: 46311 | J10: Same | K10: B01 | L10: invoices.tests and tests_trace
A11: QA10 | B11: M11 | C11: API, import and reconciliation | D11: dispatches app failures inside the suite | E11: Same run | F11: Dispatch tests pass | G11: 10 FAIL lines. 9 are consistent with brand mapping. 1 is the golden preview/commit mismatch. | H11: Failed | I11: 46311 | J11: Same | K11: B01, B02 | L11: dispatches.tests and tests_import | M11: Reconciliation file had 9 tests. How many of those 9 failed was not separated from the app total.
A12: QA11 | B12: M15 | C12: Ledger | D12: ledger app failures | E12: Same run | F12: Ledger tests pass | G12: 7 FAIL lines, brand-not-mapped 400. | H12: Failed | I12: 46311 | J12: Same | K12: B01 | L12: ledger.tests
A13: QA12 | B13: M07 | C13: Party 360 | D13: customers app failures | E13: Same run | F13: Customer tests pass | G13: 3 FAIL lines, brand-not-mapped 400. | H13: Failed | I13: 46311 | J13: Same | K13: B01 | L13: customers.tests_360
A14: QA13 | B14: M14 | C14: Notifications | D14: notifications app failures | E14: Same run | F14: Notification tests pass | G14: 2 FAIL lines, brand-not-mapped 400. | H14: Failed | I14: 46311 | J14: Same | K14: B01 | L14: notifications.tests
A15: QA14 | B15: M08 | C15: Apps with no FAIL lines | D15: brands, categories, dashboards, entities, price_lists, products, purchase_orders, reports, statements | E15: Same 264-test run | F15: No failures in these apps | G15: No FAIL lines named these apps. Individual pass counts were not printed. | H15: Passed | I15: 46311 | J15: Same | L15: FAIL inventory from the suite log | M15: Passed means no failure was recorded, not that every method was read.
A16: QA15 | B16: M06 | C16: Frontend component tests | D16: PurchaseOrderPipeline.test.tsx and similar | E16: No npm test script | F16: Would execute if a runner existed | G16: Not executed. lint and build do not run these files. | H16: Not Run | I16: 46311 | J16: Local | L16: frontend/package.json
A17: QA16 | B17: M18 | C17: Statutory calculations | D17: Trial balance, profit and loss, balance sheet | E17: Screens are sample data | F17: Posted ledger totals | G17: Not executed. Screens do not calculate from the database. | H17: Not Applicable | I17: 46311 | J17: Source inspection | K17: B04 | L17: Report screen source | M17: Not Applicable because there is no implementation to test.
A18: QA17 | B18: M11 | C18: Deployment smoke | D18: Production or staging boot | E18: No deployment target was provided | F18: App serves on the release host | G18: Not executed. Local build only. | H18: Not Run | I18: 46311 | J18: Not a server | L18: README lists localhost:8000 and localhost:5173 only
A19: QA18 | B19: M21 | C19: Database backup | D19: Backup and restore | E19: No backup file was supplied | F19: Restore proven | G19: Not executed. The backup screen does not perform one. | H19: Not Run | I19: 46311 | J19: Not run | K19: B06 | L19: BackupScreen.tsx
A20: QA19 | B20: M20 | C20: Legacy masters CRUD | D20: masters app tests | E20: No masters test module in the 264 tests | F20: CRUD tests pass | G20: Not executed. | H20: Not Run | I20: 46311 | J20: Same suite | L20: Test file list
A21: QA20 | B21: M09 | C21: PDF price import | D21: import-pdf preview and commit | E21: Feature not built | F21: Would reject a non-PDF and parse a text layer | G21: Not executed. No endpoint. | H21: Not Applicable | I21: 46311 | J21: Source inspection | L21: price_lists urls and views

Sheet Release Blockers & Risks
A1: Risk ID | B1: Module | C1: Risk Description | D1: Category | E1: Likelihood | F1: Impact | G1: Risk Level | H1: Confirmed or Suspected | I1: Release Blocking | J1: Mitigation | K1: Owner | L1: Estimated Resolution Hours | M1: Dependencies | N1: Current Status | O1: Evidence | P1: Release Decision
A2: R01 | B2: M04 | C2: Trading automated tests fail on branch-brand mapping, so invoice, dispatch and payment behaviour is unproven. | D2: Integration | E2: High | F2: High | G2: High | H2: Confirmed | I2: Yes | J2: T01 then T12. | K2: Unassigned | L2: 10 | M2: T01 | N2: Open | O2: 66 failures, 65 of this family | P2: Not Ready
A3: R02 | B3: M11 | C3: Dispatch import preview and commit differ in the golden test. | D3: Data integrity | E3: Medium | F3: High | G3: High | H3: Confirmed | I3: Yes | J3: T02. | K3: Unassigned | L3: 4 | M3: T01 | N3: Open | O3: One FAIL line | P3: Not Ready
A4: R03 | B4: M21 | C4: Year-end control changes the header year and claims a close with no server post. | D4: Data integrity | E4: High | F4: High | G4: Critical | H4: Confirmed | I4: Yes | J4: T03. Remove the screen. | K4: Unassigned | L4: 4 | M4: None | N4: Open | O4: YearEndClosingScreen.tsx | P4: Not Ready
A5: R04 | B5: M18 | C5: Statutory screens show sample figures in the live navigation. | D5: Data integrity | E5: High | F5: High | G5: High | H5: Confirmed | I5: Yes | J5: T04. Hide the screens. | K5: Unassigned | L5: 6 | M5: None | N5: Open | O5: Hard-coded report rows | P5: Not Ready
A6: R05 | B6: M19 | C6: Voucher and order-form screens do not post to the transactions tables. | D6: Integration | E6: High | F6: High | G6: High | H6: Confirmed | I6: Yes | J6: T05. Hide the screens. | K6: Unassigned | L6: 6 | M6: None | N6: Open | O6: No API calls in those screens | P6: Not Ready
A7: R06 | B7: M21 | C7: Backup screen can be mistaken for a real backup. | D7: Database | E7: High | F7: High | G7: High | H7: Confirmed | I7: Yes | J7: T06 and a real backup under T09. | K7: Unassigned | L7: 2 | M7: T09 | N7: Open | O7: BackupScreen.tsx | P7: Not Ready
A8: R07 | B8: M21 | C8: No backup or restore was shown to this audit. | D8: Database | E8: Medium | F8: High | G8: High | H8: Suspected | I8: Yes | J8: Owner confirms a backup taken before further migrations. | K8: Unassigned | L8: 2 | M8: Database owner | N8: Open | O8: Audit did not run a backup | P8: Not Ready
A9: R08 | B9: M10 | C9: 103 changed files are uncommitted on fix/rename-repair. HEAD is c326fdf. | D9: Deployment | E9: High | F9: High | G9: Critical | H9: Confirmed | I9: Yes | J9: Human review. This audit must not commit. | K9: Unassigned | L9: 8 | M9: T01 | N9: Open | O9: git diff --stat 16 Oct 2026 | P9: Not Ready
A10: R09 | B10: M01 | C10: DEBUG defaults on, and a missing secret key falls back to a dev key while DEBUG is on. Host environment was not inspected. | D10: Security | E10: Medium | F10: High | G10: High | H10: Suspected | I10: Yes | J10: Set DJANGO_DEBUG false and a real secret on the host. Do not record the secret here. | K10: Unassigned | L10: 4 | M10: Host access | N10: Open | O10: backend/config/settings.py | P10: Not Ready
A11: R10 | B11: M17 | C11: No deployment smoke test and no rollback note beyond two short READMEs. | D11: Deployment | E11: High | F11: Medium | G11: High | H11: Confirmed | I11: Yes | J11: Write the release steps and run them on a non-production host. | K11: Unassigned | L11: 6 | M11: T10, T09 | N11: Open | O11: README.md only names localhost ports | P11: Not Ready
A12: R11 | B12: M09 | C12: PDF price lists were specified and only the tables exist. | D12: Scope | E12: High | F12: Medium | G12: Medium | H12: Confirmed | I12: No | J12: Leave PDF import out of today's release. | K12: Unassigned | L12: 24 | M12: Schema already migrated | N12: Open | O12: No import-pdf route | P12: Exclude from release
A13: R12 | B13: M22 | C13: Audit screen may not show server audit rows. | D13: Integration | E13: Medium | F13: Medium | G13: Medium | H13: Confirmed | I13: No | J13: T08 after the trading blockers. | K13: Unassigned | L13: 4 | M13: None | N13: Open | O13: AuditLogScreen.tsx | P13: Known limitation
... A16: R15 | B16: M20 | C16: Legacy masters have screens and no tests in the suite that ran. | D16: Testing | E16: Medium | F16: Medium | G16: Medium | H16: Confirmed | I16: No | J16: Do not call them certified. | K16: Unassigned | L16: 3 | M16: QA19 | N16: Open | O16: No masters tests in the 264 | P16: Known limitation

Sheet Today's Delivery Plan
A1: Sequence | B1: Task ID | C1: Module | D1: Task | E1: Priority | F1: Release Blocker | G1: Estimated Hours | H1: Owner | I1: Dependencies | J1: Planned Start | K1: Planned Finish | L1: Status | M1: Acceptance Criteria | N1: Verification | O1: Notes
A2: 1 | B2: T03 | C2: M21 | D2: Disable the year-end screen so it cannot change the header year | E2: Critical | F2: Yes | G2: 2 | H2: Unassigned | I2: None | J2: 11:30 | K2: 13:30 | L2: Pending | M2: Header year unchanged after visiting the screen | N2: Browser check | O2: Smallest safe fix. Do not build a real close today.
A3: 2 | B3: T04 | C3: M18 | D3: Remove sample statutory screens from navigation | E3: High | F3: Yes | G3: 3 | H3: Unassigned | I3: None | J3: 13:30 | K3: 16:30 | L3: Pending | M3: Screens 29-35 except the live analytics report are not offered | N3: Navigation check
A4: 3 | B4: T05 | C4: M19 | D4: Remove sample voucher and order-form screens from navigation | E4: High | F4: Yes | G4: 3 | H4: Unassigned | I4: T04 | J4: 16:30 | K4: 19:30 | L4: Pending | M4: Those screens are not offered | N4: Navigation check | O4: Overlaps the end of a normal day. See capacity note.
A5: 4 | B5: T06 | C5: M21 | D5: Remove the simulated backup action | E5: High | F5: Yes | G5: 1 | H5: Unassigned | I5: None | J5: 19:30 | K5: 20:30 | L5: Pending | M5: No success message for a backup that was not taken | N5: Source check
A6: 5 | B6: T09 | C6: M21 | D6: Confirm a database backup exists | E6: Critical | F6: Yes | G6: 1 | H6: Unassigned | I6: Database owner | J6: 11:30 | K6: 12:30 | L6: Not Verified | M6: Backup identity recorded by the owner, not in this file | N6: Owner confirmation | O6: Can run in parallel with T03.
A7: 6 | B7: T01 | C7: M04 | D7: Fix brand-mapping test setup | E7: Critical | F7: Yes | G7: 8 | H7: Unassigned | I7: None | J7: Next working day | K7: Next working day | L7: Pending | M7: Suite no longer fails on unmapped brand | N7: manage.py test | O7: Does not fit after the navigation lockdown.
A8: 7 | B8: T02 | C8: M11 | D8: Fix dispatch golden preview versus commit | E8: High | F8: Yes | G8: 4 | H8: Unassigned | I8: T01 | J8: After T01 | K8: After T01 | L8: Pending | M8: Golden test passes | N8: dispatches import test
A9: 8 | B9: T12 | C9: M11 | D9: Re-run the full backend suite | E9: Critical | F9: Yes | G9: 2 | H9: Unassigned | I9: T01, T02 | J9: After T02 | K9: After T02 | L9: Pending | M9: Exit 0 or a written exception list | N9: manage.py test
A10: 9 | B10: T11 | C10: M10 | D10: Review the uncommitted tree before any tag | E10: Critical | F10: Yes | G10: 8 | H10: Unassigned | I10: T01 | J10: After tests | K10: After tests | L10: Pending | M10: Release commit matches what was reviewed | N10: git status | O10: Do not tag c326fdf plus a dirty tree.
A11: 10 | B11: T10 | C11: M01 | D11: Set production debug and secret on the host | E11: High | F11: Yes | G11: 4 | H11: Unassigned | I11: Host access | J11: Before any deploy | K11: Before any deploy | L11: Not Verified | M11: DEBUG off and secret present, values not written down here | N11: Environment names only
A12: 11 | B12: T14 | C12: M16 | D12: Click header year and month against one live list | E12: Medium | F12: No | G12: 2 | H12: Unassigned | I12: T03 | J12: If time remains | K12: If time remains | L12: Not Verified | M12: List follows the header period | N12: Browser
A13: 12 | B13: T07 | C13: M09 | D13: PDF price-list import | E13: High | F13: No | G13: 24 | H13: Unassigned | I13: Schema already applied | J13: Not today | K13: Not today | L13: Pending | M13: Out of today's scope | N13: Not scheduled | O13: Exclude from the release.
F15: Hours in this plan | G15: =SUM(G2:G13)
F16: Blocker hours (Release Blocker = Yes) | G16: =SUMIF(F2:F13,"Yes",G2:G13)
F17: Assumed hours left on 16 Oct 2026 | G17: 7
F18: Gap (negative means over capacity) | G18: =G17-G16
A20: Capacity assumption: one person, about seven hours left after 11:00 on 16 October 2026 if the day ends at 18:00. Confirm the cell highlighted above. Blocker work in this plan is far larger than seven hours. Minimum safe scope for today is not a release: disable the year-end, backup, statutory and voucher screens, and do not deploy. PDF import, the test repair and a reviewed commit do not fit today.

Sheet Release Checklist
A1: Checklist ID | B1: Category | C1: Requirement | D1: Mandatory | E1: Status | F1: Evidence | G1: Responsible Person | H1: Remarks
A2: C01 | B2: Source | C2: Source code reviewed for release | D2: Yes | E2: Not Started | F2: 103 files differ from HEAD c326fdf | G2: Unassigned | H2: Uncommitted tree
A3: C02 | B3: Frontend | C3: Frontend production build successful | D3: Yes | E3: Passed | F3: npm run build exit 0 on 16 Oct 2026 | G3: Unassigned | H3: Chunk-size warning remains
